ERROR 2021-02-22 21:35:33,801 log 11648 13012 Internal Server Error: /app01/article/
Traceback (most recent call last):
  File "C:\Python36\lib\site-packages\django\template\defaulttags.py", line 1021, in find_library
    return parser.libraries[name]
KeyError: 'my_filters_and_tags'

During handling of the above exception, another exception occurred:

Traceback (most recent call last):
  File "C:\Python36\lib\site-packages\django\core\handlers\exception.py", line 34, in inner
    response = get_response(request)
  File "C:\Python36\lib\site-packages\django\core\handlers\base.py", line 115, in _get_response
    response = self.process_exception_by_middleware(e, request)
  File "C:\Python36\lib\site-packages\django\core\handlers\base.py", line 113, in _get_response
    response = wrapped_callback(request, *callback_args, **callback_kwargs)
  File "F:\a44\keke_tl\djangoday4\project\app01\views.py", line 512, in article
    return render(request,'app01/article.html',contenxt)
  File "C:\Python36\lib\site-packages\django\shortcuts.py", line 19, in render
    content = loader.render_to_string(template_name, context, request, using=using)
  File "C:\Python36\lib\site-packages\django\template\loader.py", line 61, in render_to_string
    template = get_template(template_name, using=using)
  File "C:\Python36\lib\site-packages\django\template\loader.py", line 15, in get_template
    return engine.get_template(template_name)
  File "C:\Python36\lib\site-packages\django\template\backends\django.py", line 34, in get_template
    return Template(self.engine.get_template(template_name), self)
  File "C:\Python36\lib\site-packages\django\template\engine.py", line 143, in get_template
    template, origin = self.find_template(template_name)
  File "C:\Python36\lib\site-packages\django\template\engine.py", line 125, in find_template
    template = loader.get_template(name, skip=skip)
  File "C:\Python36\lib\site-packages\django\template\loaders\base.py", line 30, in get_template
    contents, origin, origin.template_name, self.engine,
  File "C:\Python36\lib\site-packages\django\template\base.py", line 156, in __init__
    self.nodelist = self.compile_nodelist()
  File "C:\Python36\lib\site-packages\django\template\base.py", line 194, in compile_nodelist
    return parser.parse()
  File "C:\Python36\lib\site-packages\django\template\base.py", line 477, in parse
    raise self.error(token, e)
  File "C:\Python36\lib\site-packages\django\template\base.py", line 475, in parse
    compiled_result = compile_func(self, token)
  File "C:\Python36\lib\site-packages\django\template\loader_tags.py", line 266, in do_extends
    nodelist = parser.parse()
  File "C:\Python36\lib\site-packages\django\template\base.py", line 477, in parse
    raise self.error(token, e)
  File "C:\Python36\lib\site-packages\django\template\base.py", line 475, in parse
    compiled_result = compile_func(self, token)
  File "C:\Python36\lib\site-packages\django\template\defaulttags.py", line 1078, in load
    lib = find_library(parser, name)
  File "C:\Python36\lib\site-packages\django\template\defaulttags.py", line 1025, in find_library
    name, "\n".join(sorted(parser.libraries)),
django.template.exceptions.TemplateSyntaxError: 'my_filters_and_tags' is not a registered tag library. Must be one of:
admin_list
admin_modify
admin_urls
cache
i18n
l10n
log
mptt_admin
mptt_tags
notifications_tags
static
tz
xx
ERROR 2021-02-22 21:43:55,286 log 11648 5780 Internal Server Error: /app01/article/
Traceback (most recent call last):
  File "C:\Python36\lib\site-packages\django\template\defaulttags.py", line 1021, in find_library
    return parser.libraries[name]
KeyError: 'my_filters_and_tags'

During handling of the above exception, another exception occurred:

Traceback (most recent call last):
  File "C:\Python36\lib\site-packages\django\core\handlers\exception.py", line 34, in inner
    response = get_response(request)
  File "C:\Python36\lib\site-packages\django\core\handlers\base.py", line 115, in _get_response
    response = self.process_exception_by_middleware(e, request)
  File "C:\Python36\lib\site-packages\django\core\handlers\base.py", line 113, in _get_response
    response = wrapped_callback(request, *callback_args, **callback_kwargs)
  File "F:\a44\keke_tl\djangoday4\project\app01\views.py", line 512, in article
    return render(request,'app01/article.html',contenxt)
  File "C:\Python36\lib\site-packages\django\shortcuts.py", line 19, in render
    content = loader.render_to_string(template_name, context, request, using=using)
  File "C:\Python36\lib\site-packages\django\template\loader.py", line 61, in render_to_string
    template = get_template(template_name, using=using)
  File "C:\Python36\lib\site-packages\django\template\loader.py", line 15, in get_template
    return engine.get_template(template_name)
  File "C:\Python36\lib\site-packages\django\template\backends\django.py", line 34, in get_template
    return Template(self.engine.get_template(template_name), self)
  File "C:\Python36\lib\site-packages\django\template\engine.py", line 143, in get_template
    template, origin = self.find_template(template_name)
  File "C:\Python36\lib\site-packages\django\template\engine.py", line 125, in find_template
    template = loader.get_template(name, skip=skip)
  File "C:\Python36\lib\site-packages\django\template\loaders\base.py", line 30, in get_template
    contents, origin, origin.template_name, self.engine,
  File "C:\Python36\lib\site-packages\django\template\base.py", line 156, in __init__
    self.nodelist = self.compile_nodelist()
  File "C:\Python36\lib\site-packages\django\template\base.py", line 194, in compile_nodelist
    return parser.parse()
  File "C:\Python36\lib\site-packages\django\template\base.py", line 477, in parse
    raise self.error(token, e)
  File "C:\Python36\lib\site-packages\django\template\base.py", line 475, in parse
    compiled_result = compile_func(self, token)
  File "C:\Python36\lib\site-packages\django\template\loader_tags.py", line 266, in do_extends
    nodelist = parser.parse()
  File "C:\Python36\lib\site-packages\django\template\base.py", line 477, in parse
    raise self.error(token, e)
  File "C:\Python36\lib\site-packages\django\template\base.py", line 475, in parse
    compiled_result = compile_func(self, token)
  File "C:\Python36\lib\site-packages\django\template\defaulttags.py", line 1078, in load
    lib = find_library(parser, name)
  File "C:\Python36\lib\site-packages\django\template\defaulttags.py", line 1025, in find_library
    name, "\n".join(sorted(parser.libraries)),
django.template.exceptions.TemplateSyntaxError: 'my_filters_and_tags' is not a registered tag library. Must be one of:
admin_list
admin_modify
admin_urls
cache
i18n
l10n
log
mptt_admin
mptt_tags
notifications_tags
static
tz
xx
WARNING 2021-02-22 22:10:25,229 log 7748 2744 Not Found: /favicon.ico
ERROR 2021-02-22 22:10:33,337 log 7748 2744 Internal Server Error: /app01/article/
Traceback (most recent call last):
  File "C:\Python36\lib\site-packages\django\db\backends\utils.py", line 86, in _execute
    return self.cursor.execute(sql, params)
  File "C:\Python36\lib\site-packages\django\db\backends\mysql\base.py", line 74, in execute
    return self.cursor.execute(query, args)
  File "C:\Python36\lib\site-packages\pymysql\cursors.py", line 163, in execute
    result = self._query(query)
  File "C:\Python36\lib\site-packages\pymysql\cursors.py", line 321, in _query
    conn.query(q)
  File "C:\Python36\lib\site-packages\pymysql\connections.py", line 505, in query
    self._affected_rows = self._read_query_result(unbuffered=unbuffered)
  File "C:\Python36\lib\site-packages\pymysql\connections.py", line 724, in _read_query_result
    result.read()
  File "C:\Python36\lib\site-packages\pymysql\connections.py", line 1069, in read
    first_packet = self.connection._read_packet()
  File "C:\Python36\lib\site-packages\pymysql\connections.py", line 676, in _read_packet
    packet.raise_for_error()
  File "C:\Python36\lib\site-packages\pymysql\protocol.py", line 223, in raise_for_error
    err.raise_mysql_exception(self._data)
  File "C:\Python36\lib\site-packages\pymysql\err.py", line 107, in raise_mysql_exception
    raise errorclass(errno, errval)
pymysql.err.OperationalError: (1054, "Unknown column 'app01_articlepost.likes' in 'field list'")

The above exception was the direct cause of the following exception:

Traceback (most recent call last):
  File "C:\Python36\lib\site-packages\django\core\handlers\exception.py", line 34, in inner
    response = get_response(request)
  File "C:\Python36\lib\site-packages\django\core\handlers\base.py", line 115, in _get_response
    response = self.process_exception_by_middleware(e, request)
  File "C:\Python36\lib\site-packages\django\core\handlers\base.py", line 113, in _get_response
    response = wrapped_callback(request, *callback_args, **callback_kwargs)
  File "F:\a44\keke_tl\djangoday4\project\app01\views.py", line 512, in article
    return render(request,'app01/article.html',contenxt)
  File "C:\Python36\lib\site-packages\django\shortcuts.py", line 19, in render
    content = loader.render_to_string(template_name, context, request, using=using)
  File "C:\Python36\lib\site-packages\django\template\loader.py", line 62, in render_to_string
    return template.render(context, request)
  File "C:\Python36\lib\site-packages\django\template\backends\django.py", line 61, in render
    return self.template.render(context)
  File "C:\Python36\lib\site-packages\django\template\base.py", line 171, in render
    return self._render(context)
  File "C:\Python36\lib\site-packages\django\template\base.py", line 163, in _render
    return self.nodelist.render(context)
  File "C:\Python36\lib\site-packages\django\template\base.py", line 936, in render
    bit = node.render_annotated(context)
  File "C:\Python36\lib\site-packages\django\template\base.py", line 903, in render_annotated
    return self.render(context)
  File "C:\Python36\lib\site-packages\django\template\loader_tags.py", line 150, in render
    return compiled_parent._render(context)
  File "C:\Python36\lib\site-packages\django\template\base.py", line 163, in _render
    return self.nodelist.render(context)
  File "C:\Python36\lib\site-packages\django\template\base.py", line 936, in render
    bit = node.render_annotated(context)
  File "C:\Python36\lib\site-packages\django\template\base.py", line 903, in render_annotated
    return self.render(context)
  File "C:\Python36\lib\site-packages\django\template\loader_tags.py", line 62, in render
    result = block.nodelist.render(context)
  File "C:\Python36\lib\site-packages\django\template\base.py", line 936, in render
    bit = node.render_annotated(context)
  File "C:\Python36\lib\site-packages\django\template\base.py", line 903, in render_annotated
    return self.render(context)
  File "C:\Python36\lib\site-packages\django\template\defaulttags.py", line 166, in render
    len_values = len(values)
  File "C:\Python36\lib\site-packages\django\core\paginator.py", line 150, in __len__
    return len(self.object_list)
  File "C:\Python36\lib\site-packages\django\db\models\query.py", line 258, in __len__
    self._fetch_all()
  File "C:\Python36\lib\site-packages\django\db\models\query.py", line 1261, in _fetch_all
    self._result_cache = list(self._iterable_class(self))
  File "C:\Python36\lib\site-packages\django\db\models\query.py", line 57, in __iter__
    results = compiler.execute_sql(chunked_fetch=self.chunked_fetch, chunk_size=self.chunk_size)
  File "C:\Python36\lib\site-packages\django\db\models\sql\compiler.py", line 1144, in execute_sql
    cursor.execute(sql, params)
  File "C:\Python36\lib\site-packages\django\db\backends\utils.py", line 100, in execute
    return super().execute(sql, params)
  File "C:\Python36\lib\site-packages\django\db\backends\utils.py", line 68, in execute
    return self._execute_with_wrappers(sql, params, many=False, executor=self._execute)
  File "C:\Python36\lib\site-packages\django\db\backends\utils.py", line 77, in _execute_with_wrappers
    return executor(sql, params, many, context)
  File "C:\Python36\lib\site-packages\django\db\backends\utils.py", line 86, in _execute
    return self.cursor.execute(sql, params)
  File "C:\Python36\lib\site-packages\django\db\utils.py", line 90, in __exit__
    raise dj_exc_value.with_traceback(traceback) from exc_value
  File "C:\Python36\lib\site-packages\django\db\backends\utils.py", line 86, in _execute
    return self.cursor.execute(sql, params)
  File "C:\Python36\lib\site-packages\django\db\backends\mysql\base.py", line 74, in execute
    return self.cursor.execute(query, args)
  File "C:\Python36\lib\site-packages\pymysql\cursors.py", line 163, in execute
    result = self._query(query)
  File "C:\Python36\lib\site-packages\pymysql\cursors.py", line 321, in _query
    conn.query(q)
  File "C:\Python36\lib\site-packages\pymysql\connections.py", line 505, in query
    self._affected_rows = self._read_query_result(unbuffered=unbuffered)
  File "C:\Python36\lib\site-packages\pymysql\connections.py", line 724, in _read_query_result
    result.read()
  File "C:\Python36\lib\site-packages\pymysql\connections.py", line 1069, in read
    first_packet = self.connection._read_packet()
  File "C:\Python36\lib\site-packages\pymysql\connections.py", line 676, in _read_packet
    packet.raise_for_error()
  File "C:\Python36\lib\site-packages\pymysql\protocol.py", line 223, in raise_for_error
    err.raise_mysql_exception(self._data)
  File "C:\Python36\lib\site-packages\pymysql\err.py", line 107, in raise_mysql_exception
    raise errorclass(errno, errval)
django.db.utils.OperationalError: (1054, "Unknown column 'app01_articlepost.likes' in 'field list'")
WARNING 2021-03-01 15:35:49,454 log 7508 8040 Not Found: /favicon.ico
ERROR 2021-03-01 15:36:36,000 log 7508 7708 Internal Server Error: /user/conn/
Traceback (most recent call last):
  File "F:\Python37\lib\site-packages\django\core\handlers\exception.py", line 34, in inner
    response = get_response(request)
  File "F:\Python37\lib\site-packages\django\core\handlers\base.py", line 115, in _get_response
    response = self.process_exception_by_middleware(e, request)
  File "F:\Python37\lib\site-packages\django\core\handlers\base.py", line 113, in _get_response
    response = wrapped_callback(request, *callback_args, **callback_kwargs)
  File "F:\Python37\lib\site-packages\django\utils\decorators.py", line 130, in _wrapped_view
    response = view_func(request, *args, **kwargs)
  File "F:\Python37\lib\site-packages\dwebsocket\decorators.py", line 16, in new_func
    response = func(request, *args, **kwargs)
  File "F:\a44\keke_tl\djangoday4\project\User\views.py", line 547, in conn
    i.send(message)
  File "F:\Python37\lib\site-packages\dwebsocket\backends\default\websocket.py", line 42, in send
    self.protocol.write(message)
  File "F:\Python37\lib\site-packages\dwebsocket\backends\default\protocols.py", line 239, in write
    self._write_frame(True, opcode, message)
  File "F:\Python37\lib\site-packages\dwebsocket\backends\default\protocols.py", line 211, in _write_frame
    l = len(data)
TypeError: object of type 'NoneType' has no len()
ERROR 2021-03-01 15:36:59,242 log 7508 1584 Internal Server Error: /user/conn/
Traceback (most recent call last):
  File "F:\Python37\lib\site-packages\django\core\handlers\exception.py", line 34, in inner
    response = get_response(request)
  File "F:\Python37\lib\site-packages\django\core\handlers\base.py", line 115, in _get_response
    response = self.process_exception_by_middleware(e, request)
  File "F:\Python37\lib\site-packages\django\core\handlers\base.py", line 113, in _get_response
    response = wrapped_callback(request, *callback_args, **callback_kwargs)
  File "F:\Python37\lib\site-packages\django\utils\decorators.py", line 130, in _wrapped_view
    response = view_func(request, *args, **kwargs)
  File "F:\Python37\lib\site-packages\dwebsocket\decorators.py", line 16, in new_func
    response = func(request, *args, **kwargs)
  File "F:\a44\keke_tl\djangoday4\project\User\views.py", line 547, in conn
    i.send(message)
  File "F:\Python37\lib\site-packages\dwebsocket\backends\default\websocket.py", line 42, in send
    self.protocol.write(message)
  File "F:\Python37\lib\site-packages\dwebsocket\backends\default\protocols.py", line 239, in write
    self._write_frame(True, opcode, message)
  File "F:\Python37\lib\site-packages\dwebsocket\backends\default\protocols.py", line 211, in _write_frame
    l = len(data)
TypeError: object of type 'NoneType' has no len()
ERROR 2021-03-01 16:01:13,686 log 7508 1200 Internal Server Error: /user/conn/
Traceback (most recent call last):
  File "F:\Python37\lib\site-packages\django\core\handlers\exception.py", line 34, in inner
    response = get_response(request)
  File "F:\Python37\lib\site-packages\django\core\handlers\base.py", line 115, in _get_response
    response = self.process_exception_by_middleware(e, request)
  File "F:\Python37\lib\site-packages\django\core\handlers\base.py", line 113, in _get_response
    response = wrapped_callback(request, *callback_args, **callback_kwargs)
  File "F:\Python37\lib\site-packages\django\utils\decorators.py", line 130, in _wrapped_view
    response = view_func(request, *args, **kwargs)
  File "F:\Python37\lib\site-packages\dwebsocket\decorators.py", line 16, in new_func
    response = func(request, *args, **kwargs)
  File "F:\a44\keke_tl\djangoday4\project\User\views.py", line 547, in conn
    i.send(message)
  File "F:\Python37\lib\site-packages\dwebsocket\backends\default\websocket.py", line 42, in send
    self.protocol.write(message)
  File "F:\Python37\lib\site-packages\dwebsocket\backends\default\protocols.py", line 239, in write
    self._write_frame(True, opcode, message)
  File "F:\Python37\lib\site-packages\dwebsocket\backends\default\protocols.py", line 211, in _write_frame
    l = len(data)
TypeError: object of type 'NoneType' has no len()
